from task_it.core.commons.domain.exception.not_found_exception import NotFoundException


class UserNotFoundException(NotFoundException):
    pass
